Workbook
Name CALC_REMAINED: 'Inputs & Assuptions'!$B$13:$B$72

Sheet Inputs & Assuptions
B1: Channel 1 | C1: Channel 2 | D1: Channel 3 | E1: Assumption Explanation
A2: Average Monthly Premium | B2: 600 | C2: 600 | D2: 300 | E2: Growing by 5% per annnum in all channels
A3: Premium Increase(per annum) | B3: 0.05 | C3: 0.05 | D3: 0.05
A4: Monthly Sales | B4: 6000 | C4: 1500 | D4: 1000 | E4: Growing by 5% per annnum in all channels
A5: Sales Increase(per annum) | B5: 0.05 | C5: 0.05 | D5: 0.05
A6: Commission | B6: 4 times monthly premium per sale | C6: Tiered on-going commission structure First R300 - 25% of premium R300-R600 - 20% of premium R600-R1,200 - 15% of premium R1,200-R1,500 – 10% of premium Above R1,500 – 5% of premium | D6: 20% per sale on-going commission
A7: Expenses | B7: 0.25 | C7: 0.25 | D7: 0.25 | E7: Calculated on Gross Premium
A8: Gross Claim Ratio | B8: 0.4 | C8: 0.4 | D8: 0.4
A11: Duration | B11: Lapse Rates
A12: 0 | B12: 0.42 | C12: 0.22 | D12: 0.022
A13: 1 | B13: 0.105 | C13: 0.0525 | D13: 0.005
A14: 2 | B14: 0.08 | C14: 0.04 | D14: 0.0038
A15: 3 | B15: 0.055 | C15: 0.0275 | D15: 0.0025
A16: 4 | B16: 0.05 | C16: 0.025 | D16: 0.0023
A17: 5 | B17: 0.045 | C17: 0.0225 | D17: 0.002
A18: 6 | B18: 0.04 | C18: 0.02 | D18: 0.0018
A19: 7 | B19: 0.035 | C19: 0.0175 | D19: 0.0015
A20: 8 | B20: 0.03 | C20: 0.015 | D20: 0.0013
A21: 9 | B21: 0.025 | C21: 0.0125 | D21: 0.001
A22: 10 | B22: 0.02 | C22: 0.01 | D22: 0.0008
A23: 11 | B23: 0.01 | C23: 0.005 | D23: 0.0005
... A72: 60 | B72: 0.01 | C72: 0.005 | D72: 0.0005

Sheet Summary
A14: 5 YEAR INCOME STATEMENT
A15: Year | B15: Gross Premium | C15: Commission Paid | D15: Claims Incurred | E15: Operating Expenses | F15: Net Profit/loss
A16: 1 | B16: =+B28+B36+B44 -> 2.0055016e+08 | C16: =+C28+C36+C44 -> -1.1589929e+08 | D16: =+D28+D36+D44 -> -80220063 | E16: =+E28+E36+E44 -> -50137539 | F16: =+F28+F36+F44 -> -45706736
A17: =+A16+1 -> 2 | B17: =+B29+B37+B45 -> 5.3991146e+08 | C17: =+C29+C37+C45 -> -1.5453045e+08 | D17: =+D29+D37+D45 -> -2.1596458e+08 | E17: =+E29+E37+E45 -> -1.3497786e+08 | F17: =+F29+F37+F45 -> 34438559
A18: =+A17+1 -> 3 | B18: =+B30+B38+B46 -> 8.9646135e+08 | C18: =+C30+C38+C46 -> -1.9660784e+08 | D18: =+D30+D38+D46 -> -3.5858454e+08 | E18: =+E30+E38+E46 -> -2.2411534e+08 | F18: =+F30+F38+F46 -> 1.1715363e+08
A19: =+A18+1 -> 4 | B19: =+B31+B39+B47 -> 1.2785081e+09 | C19: =+C31+C39+C47 -> -2.426181e+08 | D19: =+D31+D39+D47 -> -5.1140324e+08 | E19: =+E31+E39+E47 -> -3.1962703e+08 | F19: =+F31+F39+F47 -> 2.0485974e+08
A20: =+A19+1 -> 5 | B20: =+B32+B40+B48 -> 1.689601e+09 | C20: =+C32+C40+C48 -> -2.9300312e+08 | D20: =+D32+D40+D48 -> -6.7584041e+08 | E20: =+E32+E40+E48 -> -4.2240026e+08 | F20: =+F32+F40+F48 -> 2.9835724e+08
A26: Channel 1
A27: Year | B27: Gross Premium | C27: Commission Paid | D27: Claims Incurred | E27: Operating Expenses | F27: Net Profit/loss
A28: 1 | B28: =+SUM(OFFSET('Channel 1_calculations'!$E$6,(ROW($A28)-28)*12,0,12,1)) -> 1.2836767e+08 | C28: =+SUM(OFFSET('Channel 1_calculations'!$F$6,(ROW($A28)-28)*12,0,12,1)) -> -1.00224e+08 | D28: =+SUM(OFFSET('Channel 1_calculations'!$H$6,(ROW($A28)-28)*12,0,12,1)) -> -51347069 | E28: =+SUM(OFFSET('Channel 1_calculations'!$G$6,(ROW($A28)-28)*12,0,12,1)) -> -32091918 | F28: =+SUM(OFFSET('Channel 1_calculations'!$I$6,(ROW($A28)-28)*12,0,12,1)) -> -55295314
A29: =+A28+1 -> 2 | B29: =+SUM(OFFSET('Channel 1_calculations'!$E$6,(ROW($A29)-28)*12,0,12,1)) -> 3.3443681e+08 | C29: =+SUM(OFFSET('Channel 1_calculations'!$F$6,(ROW($A29)-28)*12,0,12,1)) -> -1.1049696e+08 | D29: =+SUM(OFFSET('Channel 1_calculations'!$H$6,(ROW($A29)-28)*12,0,12,1)) -> -1.3377472e+08 | E29: =+SUM(OFFSET('Channel 1_calculations'!$G$6,(ROW($A29)-28)*12,0,12,1)) -> -83609202 | F29: =+SUM(OFFSET('Channel 1_calculations'!$I$6,(ROW($A29)-28)*12,0,12,1)) -> 6555923.3
A30: =+A29+1 -> 3 | B30: =+SUM(OFFSET('Channel 1_calculations'!$E$6,(ROW($A30)-28)*12,0,12,1)) -> 5.4348285e+08 | C30: =+SUM(OFFSET('Channel 1_calculations'!$F$6,(ROW($A30)-28)*12,0,12,1)) -> -1.218229e+08 | D30: =+SUM(OFFSET('Channel 1_calculations'!$H$6,(ROW($A30)-28)*12,0,12,1)) -> -2.1739314e+08 | E30: =+SUM(OFFSET('Channel 1_calculations'!$G$6,(ROW($A30)-28)*12,0,12,1)) -> -1.3587071e+08 | F30: =+SUM(OFFSET('Channel 1_calculations'!$I$6,(ROW($A30)-28)*12,0,12,1)) -> 68396101
A31: =+A30+1 -> 4 | B31: =+SUM(OFFSET('Channel 1_calculations'!$E$6,(ROW($A31)-28)*12,0,12,1)) -> 7.6184554e+08 | C31: =+SUM(OFFSET('Channel 1_calculations'!$F$6,(ROW($A31)-28)*12,0,12,1)) -> -1.3430975e+08 | D31: =+SUM(OFFSET('Channel 1_calculations'!$H$6,(ROW($A31)-28)*12,0,12,1)) -> -3.0473821e+08 | E31: =+SUM(OFFSET('Channel 1_calculations'!$G$6,(ROW($A31)-28)*12,0,12,1)) -> -1.9046138e+08 | F31: =+SUM(OFFSET('Channel 1_calculations'!$I$6,(ROW($A31)-28)*12,0,12,1)) -> 1.3233619e+08
A32: =+A31+1 -> 5 | B32: =+SUM(OFFSET('Channel 1_calculations'!$E$6,(ROW($A32)-28)*12,0,12,1)) -> 9.9131902e+08 | C32: =+SUM(OFFSET('Channel 1_calculations'!$F$6,(ROW($A32)-28)*12,0,12,1)) -> -1.4807649e+08 | D32: =+SUM(OFFSET('Channel 1_calculations'!$H$6,(ROW($A32)-28)*12,0,12,1)) -> -3.9652761e+08 | E32: =+SUM(OFFSET('Channel 1_calculations'!$G$6,(ROW($A32)-28)*12,0,12,1)) -> -2.4782976e+08 | F32: =+SUM(OFFSET('Channel 1_calculations'!$I$6,(ROW($A32)-28)*12,0,12,1)) -> 1.9888516e+08
A34: Channel 2
A35: Year | B35: Gross Premium | C35: Commission Paid | D35: Claims Incurred | E35: Operating Expenses | F35: Net Profit/loss
A36: 1 | B36: =+SUM(OFFSET('Channel 2_calculations'!$E$6,(ROW($A28)-28)*12,0,12,1)) -> 49551773 | C36: =+SUM(OFFSET('Channel 2_calculations'!$F$6,(ROW($A28)-28)*12,0,12,1)) -> -11149149 | D36: =+SUM(OFFSET('Channel 2_calculations'!$H$6,(ROW($A28)-28)*12,0,12,1)) -> -19820709 | E36: =+SUM(OFFSET('Channel 2_calculations'!$G$6,(ROW($A28)-28)*12,0,12,1)) -> -12387943 | F36: =+SUM(OFFSET('Channel 2_calculations'!$I$6,(ROW($A28)-28)*12,0,12,1)) -> 6193971.6
A37: =+A36+1 -> 2 | B37: =+SUM(OFFSET('Channel 2_calculations'!$E$6,(ROW($A29)-28)*12,0,12,1)) -> 1.3713287e+08 | C37: =+SUM(OFFSET('Channel 2_calculations'!$F$6,(ROW($A29)-28)*12,0,12,1)) -> -30365135 | D37: =+SUM(OFFSET('Channel 2_calculations'!$H$6,(ROW($A29)-28)*12,0,12,1)) -> -54853148 | E37: =+SUM(OFFSET('Channel 2_calculations'!$G$6,(ROW($A29)-28)*12,0,12,1)) -> -34283217 | F37: =+SUM(OFFSET('Channel 2_calculations'!$I$6,(ROW($A29)-28)*12,0,12,1)) -> 17631369
A38: =+A37+1 -> 3 | B38: =+SUM(OFFSET('Channel 2_calculations'!$E$6,(ROW($A30)-28)*12,0,12,1)) -> 2.3238432e+08 | C38: =+SUM(OFFSET('Channel 2_calculations'!$F$6,(ROW($A30)-28)*12,0,12,1)) -> -50666105 | D38: =+SUM(OFFSET('Channel 2_calculations'!$H$6,(ROW($A30)-28)*12,0,12,1)) -> -92953728 | E38: =+SUM(OFFSET('Channel 2_calculations'!$G$6,(ROW($A30)-28)*12,0,12,1)) -> -58096080 | F38: =+SUM(OFFSET('Channel 2_calculations'!$I$6,(ROW($A30)-28)*12,0,12,1)) -> 30668407
A39: =+A38+1 -> 4 | B39: =+SUM(OFFSET('Channel 2_calculations'!$E$6,(ROW($A31)-28)*12,0,12,1)) -> 3.3648203e+08 | C39: =+SUM(OFFSET('Channel 2_calculations'!$F$6,(ROW($A31)-28)*12,0,12,1)) -> -72272243 | D39: =+SUM(OFFSET('Channel 2_calculations'!$H$6,(ROW($A31)-28)*12,0,12,1)) -> -1.3459281e+08 | E39: =+SUM(OFFSET('Channel 2_calculations'!$G$6,(ROW($A31)-28)*12,0,12,1)) -> -84120509 | F39: =+SUM(OFFSET('Channel 2_calculations'!$I$6,(ROW($A31)-28)*12,0,12,1)) -> 45496469
A40: =+A39+1 -> 5 | B40: =+SUM(OFFSET('Channel 2_calculations'!$E$6,(ROW($A32)-28)*12,0,12,1)) -> 4.5034294e+08 | C40: =+SUM(OFFSET('Channel 2_calculations'!$F$6,(ROW($A32)-28)*12,0,12,1)) -> -95338809 | D40: =+SUM(OFFSET('Channel 2_calculations'!$H$6,(ROW($A32)-28)*12,0,12,1)) -> -1.8013717e+08 | E40: =+SUM(OFFSET('Channel 2_calculations'!$G$6,(ROW($A32)-28)*12,0,12,1)) -> -1.1258573e+08 | F40: =+SUM(OFFSET('Channel 2_calculations'!$I$6,(ROW($A32)-28)*12,0,12,1)) -> 62281219
A42: Chanel 3
A43: Year | B43: Gross Premium | C43: Commission Paid | D43: Claims Incurred | E43: Operating Expenses | F43: Net Profit/loss
A44: 1 | B44: =+SUM(OFFSET('Channel 3_calculations'!$E$6,(ROW($A28)-28)*12,0,12,1)) -> 22630712 | C44: =+SUM(OFFSET('Channel 3_calculations'!$F$6,(ROW($A28)-28)*12,0,12,1)) -> -4526142.3 | D44: =+SUM(OFFSET('Channel 3_calculations'!$H$6,(ROW($A28)-28)*12,0,12,1)) -> -9052284.6 | E44: =+SUM(OFFSET('Channel 3_calculations'!$G$6,(ROW($A28)-28)*12,0,12,1)) -> -5657677.9 | F44: =+SUM(OFFSET('Channel 3_calculations'!$I$6,(ROW($A28)-28)*12,0,12,1)) -> 3394606.7
A45: =+A44+1 -> 2 | B45: =+SUM(OFFSET('Channel 3_calculations'!$E$6,(ROW($A29)-28)*12,0,12,1)) -> 68341780 | C45: =+SUM(OFFSET('Channel 3_calculations'!$F$6,(ROW($A29)-28)*12,0,12,1)) -> -13668356 | D45: =+SUM(OFFSET('Channel 3_calculations'!$H$6,(ROW($A29)-28)*12,0,12,1)) -> -27336712 | E45: =+SUM(OFFSET('Channel 3_calculations'!$G$6,(ROW($A29)-28)*12,0,12,1)) -> -17085445 | F45: =+SUM(OFFSET('Channel 3_calculations'!$I$6,(ROW($A29)-28)*12,0,12,1)) -> 10251267
A46: =+A45+1 -> 3 | B46: =+SUM(OFFSET('Channel 3_calculations'!$E$6,(ROW($A30)-28)*12,0,12,1)) -> 1.2059418e+08 | C46: =+SUM(OFFSET('Channel 3_calculations'!$F$6,(ROW($A30)-28)*12,0,12,1)) -> -24118836 | D46: =+SUM(OFFSET('Channel 3_calculations'!$H$6,(ROW($A30)-28)*12,0,12,1)) -> -48237672 | E46: =+SUM(OFFSET('Channel 3_calculations'!$G$6,(ROW($A30)-28)*12,0,12,1)) -> -30148545 | F46: =+SUM(OFFSET('Channel 3_calculations'!$I$6,(ROW($A30)-28)*12,0,12,1)) -> 18089127
A47: =+A46+1 -> 4 | B47: =+SUM(OFFSET('Channel 3_calculations'!$E$6,(ROW($A31)-28)*12,0,12,1)) -> 1.8018054e+08 | C47: =+SUM(OFFSET('Channel 3_calculations'!$F$6,(ROW($A31)-28)*12,0,12,1)) -> -36036108 | D47: =+SUM(OFFSET('Channel 3_calculations'!$H$6,(ROW($A31)-28)*12,0,12,1)) -> -72072217 | E47: =+SUM(OFFSET('Channel 3_calculations'!$G$6,(ROW($A31)-28)*12,0,12,1)) -> -45045135 | F47: =+SUM(OFFSET('Channel 3_calculations'!$I$6,(ROW($A31)-28)*12,0,12,1)) -> 27027081
A48: =+A47+1 -> 5 | B48: =+SUM(OFFSET('Channel 3_calculations'!$E$6,(ROW($A32)-28)*12,0,12,1)) -> 2.4793908e+08 | C48: =+SUM(OFFSET('Channel 3_calculations'!$F$6,(ROW($A32)-28)*12,0,12,1)) -> -49587815 | D48: =+SUM(OFFSET('Channel 3_calculations'!$H$6,(ROW($A32)-28)*12,0,12,1)) -> -99175630 | E48: =+SUM(OFFSET('Channel 3_calculations'!$G$6,(ROW($A32)-28)*12,0,12,1)) -> -61984769 | F48: =+SUM(OFFSET('Channel 3_calculations'!$I$6,(ROW($A32)-28)*12,0,12,1)) -> 37190861

Sheet Visuals
A1: Cummulative Net Cashflow | Q1: Revenue Cashflow
A2: Months | B2: Channel 1 | C2: Channel 2 | D2: Channel 3 | E2: Total | Q2: Year | R2: Channel 1 | S2: Channel 2 | T2: Channel 3 | U2: Total_Revenue | V2: Net Profit/loss | W2: Margin
A3: 1 | B3: =+'Channel 1_calculations'!J6 -> -7621200 | C3: =+'Channel 2_calculations'!J6 -> 87750 | D3: =+'Channel 3_calculations'!J6 -> 44010 | E3: =+SUM(B3:D3) -> -7489440 | Q3: 1 | R3: =+SUM(OFFSET('Channel 1_calculations'!$E$6,(ROW(Visuals!Q3)-3)*12,0,12,1)) -> 1.2836767e+08 | S3: =+SUM(OFFSET('Channel 2_calculations'!$E$6,(ROW(Visuals!Q3)-3)*12,0,12,1)) -> 49551773 | T3: =+SUM(OFFSET('Channel 3_calculations'!$E$6,(ROW(Visuals!Q3)-3)*12,0,12,1)) -> 22630712 | U3: =+SUM(R3:T3) -> 2.0055016e+08 | V3: =+Summary!F16 -> -45706736
A4: =+A3+1 -> 2 | B4: =+'Channel 1_calculations'!J7 -> -14588334 | C4: =+'Channel 2_calculations'!J7 -> 258643.12 | D4: =+'Channel 3_calculations'!J7 -> 131809.95 | E4: =+SUM(B4:D4) -> -14197881 | Q4: =+Q3+1 -> 2 | R4: =+SUM(OFFSET('Channel 1_calculations'!$E$6,(ROW(Visuals!Q4)-3)*12,0,12,1)) -> 3.3443681e+08 | S4: =+SUM(OFFSET('Channel 2_calculations'!$E$6,(ROW(Visuals!Q4)-3)*12,0,12,1)) -> 1.3713287e+08 | T4: =+SUM(OFFSET('Channel 3_calculations'!$E$6,(ROW(Visuals!Q4)-3)*12,0,12,1)) -> 68341780 | U4: =+SUM(R4:T4) -> 5.3991146e+08 | V4: =+Summary!F17 -> 34438559
A5: =+A4+1 -> 3 | B5: =+'Channel 1_calculations'!J8 -> -20953727 | C5: =+'Channel 2_calculations'!J8 -> 509353.65 | D5: =+'Channel 3_calculations'!J8 -> 263233.45 | E5: =+SUM(B5:D5) -> -20181140 | Q5: =+Q4+1 -> 3 | R5: =+SUM(OFFSET('Channel 1_calculations'!$E$6,(ROW(Visuals!Q5)-3)*12,0,12,1)) -> 5.4348285e+08 | S5: =+SUM(OFFSET('Channel 2_calculations'!$E$6,(ROW(Visuals!Q5)-3)*12,0,12,1)) -> 2.3238432e+08 | T5: =+SUM(OFFSET('Channel 3_calculations'!$E$6,(ROW(Visuals!Q5)-3)*12,0,12,1)) -> 1.2059418e+08 | U5: =+SUM(R5:T5) -> 8.9646135e+08 | V5: =+Summary!F18 -> 1.1715363e+08
A6: =+A5+1 -> 4 | B6: =+'Channel 1_calculations'!J9 -> -26750476 | C6: =+'Channel 2_calculations'!J9 -> 925436.6 | D6: =+'Channel 3_calculations'!J9 -> 438171.44 | E6: =+SUM(B6:D6) -> -25386868 | Q6: =+Q5+1 -> 4 | R6: =+SUM(OFFSET('Channel 1_calculations'!$E$6,(ROW(Visuals!Q6)-3)*12,0,12,1)) -> 7.6184554e+08 | S6: =+SUM(OFFSET('Channel 2_calculations'!$E$6,(ROW(Visuals!Q6)-3)*12,0,12,1)) -> 3.3648203e+08 | T6: =+SUM(OFFSET('Channel 3_calculations'!$E$6,(ROW(Visuals!Q6)-3)*12,0,12,1)) -> 1.8018054e+08 | U6: =+SUM(R6:T6) -> 1.2785081e+09 | V6: =+Summary!F19 -> 2.0485974e+08
A7: =+A6+1 -> 5 | B7: =+'Channel 1_calculations'!J10 -> -32007011 | C7: =+'Channel 2_calculations'!J10 -> 1334058.3 | D7: =+'Channel 3_calculations'!J10 -> 656523.83 | E7: =+SUM(B7:D7) -> -30016429 | Q7: =+Q6+1 -> 5 | R7: =+SUM(OFFSET('Channel 1_calculations'!$E$6,(ROW(Visuals!Q7)-3)*12,0,12,1)) -> 9.9131902e+08 | S7: =+SUM(OFFSET('Channel 2_calculations'!$E$6,(ROW(Visuals!Q7)-3)*12,0,12,1)) -> 4.5034294e+08 | T7: =+SUM(OFFSET('Channel 3_calculations'!$E$6,(ROW(Visuals!Q7)-3)*12,0,12,1)) -> 2.4793908e+08 | U7: =+SUM(R7:T7) -> 1.689601e+09 | V7: =+Summary!F20 -> 2.9835724e+08 | W7: =+(V7/U7) -> 0.17658443
A8: =+A7+1 -> 6 | B8: =+'Channel 1_calculations'!J11 -> -36747644 | C8: =+'Channel 2_calculations'!J11 -> 1816474.7 | D8: =+'Channel 3_calculations'!J11 -> 918203.8 | E8: =+SUM(B8:D8) -> -34012965
A9: =+A8+1 -> 7 | B9: =+'Channel 1_calculations'!J12 -> -40993009 | C9: =+'Channel 2_calculations'!J12 -> 2371268.9 | D9: =+'Channel 3_calculations'!J12 -> 1223133.4 | E9: =+SUM(B9:D9) -> -37398607
A10: =+A9+1 -> 8 | B10: =+'Channel 1_calculations'!J13 -> -44760442 | C10: =+'Channel 2_calculations'!J13 -> 2997186.4 | D10: =+'Channel 3_calculations'!J13 -> 1571247.6 | E10: =+SUM(B10:D10) -> -40192008
A11: =+A10+1 -> 9 | B11: =+'Channel 1_calculations'!J14 -> -48064280 | C11: =+'Channel 2_calculations'!J14 -> 3693171.7 | D11: =+'Channel 3_calculations'!J14 -> 1962490.5 | E11: =+SUM(B11:D11) -> -42408617
A12: =+A11+1 -> 10 | B12: =+'Channel 1_calculations'!J15 -> -50916113 | C12: =+'Channel 2_calculations'!J15 -> 4458360.2 | D12: =+'Channel 3_calculations'!J15 -> 2396818.8 | E12: =+SUM(B12:D12) -> -44060934
A13: =+A12+1 -> 11 | B13: =+'Channel 1_calculations'!J16 -> -53324981 | C13: =+'Channel 2_calculations'!J16 -> 5292070.8 | D13: =+'Channel 3_calculations'!J16 -> 2874198 | E13: =+SUM(B13:D13) -> -45158712 | R13: =+ROW(Visuals!Q3) -> 3
A14: =+A13+1 -> 12 | B14: =+'Channel 1_calculations'!J17 -> -55295314 | C14: =+'Channel 2_calculations'!J17 -> 6193971.6 | D14: =+'Channel 3_calculations'!J17 -> 3394606.7 | E14: =+SUM(B14:D14) -> -45706736
A15: =+A14+1 -> 13 | B15: =+'Channel 1_calculations'!J18 -> -57308420 | C15: =+'Channel 2_calculations'!J18 -> 7246051.2 | D15: =+'Channel 3_calculations'!J18 -> 3988504.8 | E15: =+SUM(B15:D15) -> -46073864
A16: =+A15+1 -> 14 | B16: =+'Channel 1_calculations'!J19 -> -58835889 | C16: =+'Channel 2_calculations'!J19 -> 8375553.3 | D16: =+'Channel 3_calculations'!J19 -> 4629837.5 | E16: =+SUM(B16:D16) -> -45830498
A17: =+A16+1 -> 15 | B17: =+'Channel 1_calculations'!J20 -> -59884980 | C17: =+'Channel 2_calculations'!J20 -> 9581954.1 | D17: =+'Channel 3_calculations'!J20 -> 5318573.6 | E17: =+SUM(B17:D17) -> -44984453
A18: =+A17+1 -> 16 | B18: =+'Channel 1_calculations'!J21 -> -60461900 | C18: =+'Channel 2_calculations'!J21 -> 10864772 | D18: =+'Channel 3_calculations'!J21 -> 6054684.9 | E18: =+SUM(B18:D18) -> -43542443
A19: =+A18+1 -> 17 | B19: =+'Channel 1_calculations'!J22 -> -60572564 | C19: =+'Channel 2_calculations'!J22 -> 12223542 | D19: =+'Channel 3_calculations'!J22 -> 6838143.6 | E19: =+SUM(B19:D19) -> -41510879
A20: =+A19+1 -> 18 | B20: =+'Channel 1_calculations'!J23 -> -60222628 | C20: =+'Channel 2_calculations'!J23 -> 13657812 | D20: =+'Channel 3_calculations'!J23 -> 7668922.5 | E20: =+SUM(B20:D20) -> -38895893
A21: =+A20+1 -> 19 | B21: =+'Channel 1_calculations'!J24 -> -59417509 | C21: =+'Channel 2_calculations'!J24 -> 15167145 | D21: =+'Channel 3_calculations'!J24 -> 8546995 | E21: =+SUM(B21:D21) -> -35703370
A22: =+A21+1 -> 20 | B22: =+'Channel 1_calculations'!J25 -> -58162411 | C22: =+'Channel 2_calculations'!J25 -> 16751116 | D22: =+'Channel 3_calculations'!J25 -> 9472335.2 | E22: =+SUM(B22:D22) -> -31938960
A23: =+A22+1 -> 21 | B23: =+'Channel 1_calculations'!J26 -> -56462333 | C23: =+'Channel 2_calculations'!J26 -> 18409314 | D23: =+'Channel 3_calculations'!J26 -> 10444918 | E23: =+SUM(B23:D23) -> -27608102
A24: =+A23+1 -> 22 | B24: =+'Channel 1_calculations'!J27 -> -54322092 | C24: =+'Channel 2_calculations'!J27 -> 20141339 | D24: =+'Channel 3_calculations'!J27 -> 11464718 | E24: =+SUM(B24:D24) -> -22716036
A25: =+A24+1 -> 23 | B25: =+'Channel 1_calculations'!J28 -> -51746326 | C25: =+'Channel 2_calculations'!J28 -> 21946804 | D25: =+'Channel 3_calculations'!J28 -> 12531711 | E25: =+SUM(B25:D25) -> -17267812
... A62: =+A61+1 -> 60 | B62: =+'Channel 1_calculations'!J65 -> 3.5087807e+08 | C62: =+'Channel 2_calculations'!J65 -> 1.6227144e+08 | D62: =+'Channel 3_calculations'!J65 -> 95952943 | E62: =+SUM(B62:D62) -> 6.0910244e+08

Sheet Channel 1_calculations
B1: Monthly_premium | C1: =+'Inputs & Assuptions'!$B$2 -> 600 | E1: Commission_rate | F1: 4
B2: Premium_Increase | C2: =+'Inputs & Assuptions'!$B$3 -> 0.05 | E2: Expenses_rate | F2: =+'Inputs & Assuptions'!$B$7 -> 0.25
B3: Gross Claim Ratio | C3: =+'Inputs & Assuptions'!$B$8 -> 0.4
A5: Months | B5: New_sales | C5: Active Policies | D5: Premium | E5: Gross_Premium | F5: Commission | G5: Expenses | H5: Claims | I5: Net Gain/Loss | J5: CummulativeNet Gain/Loss
A6: 1 | B6: =+'Channel 1 Sales'!C6 -> 3480 | C6: {=+TRANSPOSE('Channel 1 Sales'!$F$67:$BM$67)} -> 3480 | D6: =IF(MOD($A6, 12) = 0, $C$1 * 1.05, $C$1) -> 600 | E6: =+C6*D6 -> 2088000 | F6: =-$F$1*B6*D6 -> -8352000 | G6: =-E6*$F$2 -> -522000 | H6: =-E6*$C$3 -> -835200 | I6: =+E6+F6+G6+H6 -> -7621200 | J6: =+I6 -> -7621200
A7: =+A6+1 -> 2 | B7: =+'Channel 1 Sales'!C7 -> 3480 | C7: 6594.6 | D7: =IF(MOD($A7-1, 12) = 0, D6 * 1.05, D6) -> 600 | E7: =+C7*D7 -> 3956760 | F7: =-$F$1*B7*D7 -> -8352000 | G7: =-E7*$F$2 -> -989190 | H7: =-E7*$C$3 -> -1582704 | I7: =+E7+F7+G7+H7 -> -6967134 | J7: =+J6+I7 -> -14588334
A8: =+A7+1 -> 3 | B8: =+'Channel 1 Sales'!C8 -> 3480 | C8: 9460.032 | D8: =IF(MOD($A8-1, 12) = 0, D7 * 1.05, D7) -> 600 | E8: =+C8*D8 -> 5676019.2 | F8: =-$F$1*B8*D8 -> -8352000 | G8: =-E8*$F$2 -> -1419004.8 | H8: =-E8*$C$3 -> -2270407.7 | I8: =+E8+F8+G8+H8 -> -6365393.3 | J8: =+J7+I8 -> -20953727
A9: =+A8+1 -> 4 | B9: =+'Channel 1 Sales'!C9 -> 3480 | C9: 12167.865 | D9: =IF(MOD($A9-1, 12) = 0, D8 * 1.05, D8) -> 600 | E9: =+C9*D9 -> 7300719.1 | F9: =-$F$1*B9*D9 -> -8352000 | G9: =-E9*$F$2 -> -1825179.8 | H9: =-E9*$C$3 -> -2920287.7 | I9: =+E9+F9+G9+H9 -> -5796748.3 | J9: =+J8+I9 -> -26750476
A10: =+A9+1 -> 5 | B10: =+'Channel 1 Sales'!C10 -> 3480 | C10: 14740.307 | D10: =IF(MOD($A10-1, 12) = 0, D9 * 1.05, D9) -> 600 | E10: =+C10*D10 -> 8844184.1 | F10: =-$F$1*B10*D10 -> -8352000 | G10: =-E10*$F$2 -> -2211046 | H10: =-E10*$C$3 -> -3537673.6 | I10: =+E10+F10+G10+H10 -> -5256535.6 | J10: =+J9+I10 -> -32007011
A11: =+A10+1 -> 6 | B11: =+'Channel 1 Sales'!C11 -> 3480 | C11: 17196.989 | D11: =IF(MOD($A11-1, 12) = 0, D10 * 1.05, D10) -> 600 | E11: =+C11*D11 -> 10318193 | F11: =-$F$1*B11*D11 -> -8352000 | G11: =-E11*$F$2 -> -2579548.3 | H11: =-E11*$C$3 -> -4127277.2 | I11: =+E11+F11+G11+H11 -> -4740632.4 | J11: =+J10+I11 -> -36747644
A12: =+A11+1 -> 7 | B12: =+'Channel 1 Sales'!C12 -> 3480 | C12: 19555.403 | D12: =IF(MOD($A12-1, 12) = 0, D11 * 1.05, D11) -> 600 | E12: =+C12*D12 -> 11733242 | F12: =-$F$1*B12*D12 -> -8352000 | G12: =-E12*$F$2 -> -2933310.4 | H12: =-E12*$C$3 -> -4693296.7 | I12: =+E12+F12+G12+H12 -> -4245365.4 | J12: =+J11+I12 -> -40993009
A13: =+A12+1 -> 8 | B13: =+'Channel 1 Sales'!C13 -> 3480 | C13: 21831.273 | D13: =IF(MOD($A13-1, 12) = 0, D12 * 1.05, D12) -> 600 | E13: =+C13*D13 -> 13098764 | F13: =-$F$1*B13*D13 -> -8352000 | G13: =-E13*$F$2 -> -3274690.9 | H13: =-E13*$C$3 -> -5239505.5 | I13: =+E13+F13+G13+H13 -> -3767432.7 | J13: =+J12+I13 -> -44760442
A14: =+A13+1 -> 9 | B14: =+'Channel 1 Sales'!C14 -> 3480 | C14: 24038.867 | D14: =IF(MOD($A14-1, 12) = 0, D13 * 1.05, D13) -> 600 | E14: =+C14*D14 -> 14423320 | F14: =-$F$1*B14*D14 -> -8352000 | G14: =-E14*$F$2 -> -3605830 | H14: =-E14*$C$3 -> -5769328 | I14: =+E14+F14+G14+H14 -> -3303838 | J14: =+J13+I14 -> -48064280
A15: =+A14+1 -> 10 | B15: =+'Channel 1 Sales'!C15 -> 3480 | C15: 26191.271 | D15: =IF(MOD($A15-1, 12) = 0, D14 * 1.05, D14) -> 600 | E15: =+C15*D15 -> 15714762 | F15: =-$F$1*B15*D15 -> -8352000 | G15: =-E15*$F$2 -> -3928690.6 | H15: =-E15*$C$3 -> -6285905 | I15: =+E15+F15+G15+H15 -> -2851833.1 | J15: =+J14+I15 -> -50916113
A16: =+A15+1 -> 11 | B16: =+'Channel 1 Sales'!C16 -> 3480 | C16: 28300.627 | D16: =IF(MOD($A16-1, 12) = 0, D15 * 1.05, D15) -> 600 | E16: =+C16*D16 -> 16980376 | F16: =-$F$1*B16*D16 -> -8352000 | G16: =-E16*$F$2 -> -4245094 | H16: =-E16*$C$3 -> -6792150.4 | I16: =+E16+F16+G16+H16 -> -2408868.4 | J16: =+J15+I16 -> -53324981
A17: =+A16+1 -> 12 | B17: =+'Channel 1 Sales'!C17 -> 3480 | C17: 30388.889 | D17: =IF(MOD($A17-1, 12) = 0, D16 * 1.05, D16) -> 600 | E17: =+C17*D17 -> 18233333 | F17: =-$F$1*B17*D17 -> -8352000 | G17: =-E17*$F$2 -> -4558333.3 | H17: =-E17*$C$3 -> -7293333.4 | I17: =+E17+F17+G17+H17 -> -1970333.3 | J17: =+J16+I17 -> -55295314
A18: =+A17+1 -> 13 | B18: =+'Channel 1 Sales'!C18 -> 3654 | C18: 32630.269 | D18: =IF(MOD($A18-1, 12) = 0, D17 * 1.05, D17) -> 630 | E18: =+C18*D18 -> 20557069 | F18: =-$F$1*B18*D18 -> -9208080 | G18: =-E18*$F$2 -> -5139267.3 | H18: =-E18*$C$3 -> -8222827.7 | I18: =+E18+F18+G18+H18 -> -2013105.7 | J18: =+J17+I18 -> -57308420
... A65: =+A64+1 -> 60 | B65: =+'Channel 1 Sales'!C65 -> 4229.9618 | C65: 122817.69 | D65: =IF(MOD($A65-1, 12) = 0, D64 * 1.05, D64) -> 729.30375 | E65: =+C65*D65 -> 89571403 | F65: =-$F$1*B65*D65 -> -12339708 | G65: =-E65*$F$2 -> -22392851 | H65: =-E65*$C$3 -> -35828561 | I65: =+E65+F65+G65+H65 -> 19010283 | J65: =+J64+I65 -> 3.5087807e+08

Sheet Channel 2_calculations
B1: Monthl_premium | C1: =+'Inputs & Assuptions'!$C$2 -> 600 | E1: Commission_rate | F1: Regressive Tiered | H1: =IF(MOD($A1, 12) = 0, $C$1 * 1.05, $C$1) -> 630
B2: Premium_Increase | C2: =+'Inputs & Assuptions'!$C$3 -> 0.05 | E2: Expenses_rate | F2: =+'Inputs & Assuptions'!$C$7 -> 0.25 | H2: =IF(MOD($A2-1, 12) = 0, H1 * 1.05, H1) -> 630
B3: Gross Claim Ratio | C3: =+'Inputs & Assuptions'!$C$8 -> 0.4
A5: Months | B5: New_sales | C5: Active Policies | D5: Premium | E5: Gross_Premium | F5: Commission | G5: Expenses | H5: Claims | I5: Net Gain/Loss | J5: CummulativeNet Gain/Loss
A6: 1 | B6: =+'Channel 2 Sales'!C6 -> 1170 | C6: {=+TRANSPOSE('Channel 2 Sales'!$F$67:$BM$67)} -> 1170 | D6: =IF(MOD($A6, 12) = 0, $C$1 * 1.05, $C$1) -> 600 | E6: =+C6*D6 -> 702000 | F6: =-((D6*25%)-(MAX(0,(D6-300))*5%)-(MAX(0,(D6-600))*5%)-(MAX(0,(D6-1200))*5%)-(MAX(0,(D6-1500))*5%))*C6 -> -157950 | G6: =-E6*$F$2 -> -175500 | H6: =-E6*$C$3 -> -280800 | I6: =+E6+F6+G6+H6 -> 87750 | J6: =+I6 -> 87750
A7: =+A6+1 -> 2 | B7: =+'Channel 2 Sales'!C7 -> 1170 | C7: 2278.575 | D7: =IF(MOD($A7-1, 12) = 0, D6 * 1.05, D6) -> 600 | E7: =+C7*D7 -> 1367145 | F7: =-((D7*25%)-(MAX(0,(D7-300))*5%)-(MAX(0,(D7-600))*5%)-(MAX(0,(D7-1200))*5%)-(MAX(0,(D7-1500))*5%))*C7 -> -307607.62 | G7: =-E7*$F$2 -> -341786.25 | H7: =-E7*$C$3 -> -546858 | I7: =+E7+F7+G7+H7 -> 170893.12 | J7: =+J6+I7 -> 258643.12
A8: =+A7+1 -> 3 | B8: =+'Channel 2 Sales'!C8 -> 1170 | C8: 3342.807 | D8: =IF(MOD($A8-1, 12) = 0, D7 * 1.05, D7) -> 600 | E8: =+C8*D8 -> 2005684.2 | F8: =-((D8*25%)-(MAX(0,(D8-300))*5%)-(MAX(0,(D8-600))*5%)-(MAX(0,(D8-1200))*5%)-(MAX(0,(D8-1500))*5%))*C8 -> -451278.94 | G8: =-E8*$F$2 -> -501421.05 | H8: =-E8*$C$3 -> -802273.68 | I8: =+E8+F8+G8+H8 -> 250710.52 | J8: =+J7+I8 -> 509353.65
A9: =+A8+1 -> 4 | B9: =+'Channel 2 Sales'!C9 -> 1170 | C9: 5547.7726 | D9: =IF(MOD($A9-1, 12) = 0, D8 * 1.05, D8) -> 600 | E9: =+C9*D9 -> 3328663.6 | F9: =-((D9*25%)-(MAX(0,(D9-300))*5%)-(MAX(0,(D9-600))*5%)-(MAX(0,(D9-1200))*5%)-(MAX(0,(D9-1500))*5%))*C9 -> -748949.3 | G9: =-E9*$F$2 -> -832165.89 | H9: =-E9*$C$3 -> -1331465.4 | I9: =+E9+F9+G9+H9 -> 416082.95 | J9: =+J8+I9 -> 925436.6
A10: =+A9+1 -> 5 | B10: =+'Channel 2 Sales'!C10 -> 1170 | C10: 5448.2891 | D10: =IF(MOD($A10-1, 12) = 0, D9 * 1.05, D9) -> 600 | E10: =+C10*D10 -> 3268973.5 | F10: =-((D10*25%)-(MAX(0,(D10-300))*5%)-(MAX(0,(D10-600))*5%)-(MAX(0,(D10-1200))*5%)-(MAX(0,(D10-1500))*5%))*C10 -> -735519.03 | G10: =-E10*$F$2 -> -817243.36 | H10: =-E10*$C$3 -> -1307589.4 | I10: =+E10+F10+G10+H10 -> 408621.68 | J10: =+J9+I10 -> 1334058.3
A11: =+A10+1 -> 6 | B11: =+'Channel 2 Sales'!C11 -> 1170 | C11: 6432.219 | D11: =IF(MOD($A11-1, 12) = 0, D10 * 1.05, D10) -> 600 | E11: =+C11*D11 -> 3859331.4 | F11: =-((D11*25%)-(MAX(0,(D11-300))*5%)-(MAX(0,(D11-600))*5%)-(MAX(0,(D11-1200))*5%)-(MAX(0,(D11-1500))*5%))*C11 -> -868349.57 | G11: =-E11*$F$2 -> -964832.85 | H11: =-E11*$C$3 -> -1543732.6 | I11: =+E11+F11+G11+H11 -> 482416.43 | J11: =+J10+I11 -> 1816474.7
A12: =+A11+1 -> 7 | B12: =+'Channel 2 Sales'!C12 -> 1170 | C12: 7397.2566 | D12: =IF(MOD($A12-1, 12) = 0, D11 * 1.05, D11) -> 600 | E12: =+C12*D12 -> 4438354 | F12: =-((D12*25%)-(MAX(0,(D12-300))*5%)-(MAX(0,(D12-600))*5%)-(MAX(0,(D12-1200))*5%)-(MAX(0,(D12-1500))*5%))*C12 -> -998629.64 | G12: =-E12*$F$2 -> -1109588.5 | H12: =-E12*$C$3 -> -1775341.6 | I12: =+E12+F12+G12+H12 -> 554794.24 | J12: =+J11+I12 -> 2371268.9
A13: =+A12+1 -> 8 | B13: =+'Channel 2 Sales'!C13 -> 1170 | C13: 8345.5656 | D13: =IF(MOD($A13-1, 12) = 0, D12 * 1.05, D12) -> 600 | E13: =+C13*D13 -> 5007339.3 | F13: =-((D13*25%)-(MAX(0,(D13-300))*5%)-(MAX(0,(D13-600))*5%)-(MAX(0,(D13-1200))*5%)-(MAX(0,(D13-1500))*5%))*C13 -> -1126651.4 | G13: =-E13*$F$2 -> -1251834.8 | H13: =-E13*$C$3 -> -2002935.7 | I13: =+E13+F13+G13+H13 -> 625917.42 | J13: =+J12+I13 -> 2997186.4
A14: =+A13+1 -> 9 | B14: =+'Channel 2 Sales'!C14 -> 1170 | C14: 9279.804 | D14: =IF(MOD($A14-1, 12) = 0, D13 * 1.05, D13) -> 600 | E14: =+C14*D14 -> 5567882.4 | F14: =-((D14*25%)-(MAX(0,(D14-300))*5%)-(MAX(0,(D14-600))*5%)-(MAX(0,(D14-1200))*5%)-(MAX(0,(D14-1500))*5%))*C14 -> -1252773.5 | G14: =-E14*$F$2 -> -1391970.6 | H14: =-E14*$C$3 -> -2227153 | I14: =+E14+F14+G14+H14 -> 695985.3 | J14: =+J13+I14 -> 3693171.7
A15: =+A14+1 -> 10 | B15: =+'Channel 2 Sales'!C15 -> 1170 | C15: 10202.514 | D15: =IF(MOD($A15-1, 12) = 0, D14 * 1.05, D14) -> 600 | E15: =+C15*D15 -> 6121508.2 | F15: =-((D15*25%)-(MAX(0,(D15-300))*5%)-(MAX(0,(D15-600))*5%)-(MAX(0,(D15-1200))*5%)-(MAX(0,(D15-1500))*5%))*C15 -> -1377339.4 | G15: =-E15*$F$2 -> -1530377.1 | H15: =-E15*$C$3 -> -2448603.3 | I15: =+E15+F15+G15+H15 -> 765188.53 | J15: =+J14+I15 -> 4458360.2
A16: =+A15+1 -> 11 | B16: =+'Channel 2 Sales'!C16 -> 1170 | C16: 11116.141 | D16: =IF(MOD($A16-1, 12) = 0, D15 * 1.05, D15) -> 600 | E16: =+C16*D16 -> 6669684.7 | F16: =-((D16*25%)-(MAX(0,(D16-300))*5%)-(MAX(0,(D16-600))*5%)-(MAX(0,(D16-1200))*5%)-(MAX(0,(D16-1500))*5%))*C16 -> -1500679.1 | G16: =-E16*$F$2 -> -1667421.2 | H16: =-E16*$C$3 -> -2667873.9 | I16: =+E16+F16+G16+H16 -> 833710.59 | J16: =+J15+I16 -> 5292070.8
A17: =+A16+1 -> 12 | B17: =+'Channel 2 Sales'!C17 -> 1170 | C17: 12025.344 | D17: =IF(MOD($A17-1, 12) = 0, D16 * 1.05, D16) -> 600 | E17: =+C17*D17 -> 7215206.3 | F17: =-((D17*25%)-(MAX(0,(D17-300))*5%)-(MAX(0,(D17-600))*5%)-(MAX(0,(D17-1200))*5%)-(MAX(0,(D17-1500))*5%))*C17 -> -1623421.4 | G17: =-E17*$F$2 -> -1803801.6 | H17: =-E17*$C$3 -> -2886082.5 | I17: =+E17+F17+G17+H17 -> 901900.78 | J17: =+J16+I17 -> 6193971.6
A18: =+A17+1 -> 13 | B18: =+'Channel 2 Sales'!C18 -> 1228.5 | C18: 12988.638 | D18: =IF(MOD($A18-1, 12) = 0, D17 * 1.05, D17) -> 630 | E18: =+C18*D18 -> 8182841.8 | F18: =-((D18*25%)-(MAX(0,(D18-300))*5%)-(MAX(0,(D18-600))*5%)-(MAX(0,(D18-1200))*5%)-(MAX(0,(D18-1500))*5%))*C18 -> -1811915 | G18: =-E18*$F$2 -> -2045710.5 | H18: =-E18*$C$3 -> -3273136.7 | I18: =+E18+F18+G18+H18 -> 1052079.7 | J18: =+J17+I18 -> 7246051.2
... A65: =+A64+1 -> 60 | B65: =+'Channel 2 Sales'!C65 -> 1422.1423 | C65: 56474.361 | D65: =IF(MOD($A65-1, 12) = 0, D64 * 1.05, D64) -> 729.30375 | E65: =+C65*D65 -> 41186963 | F65: =-((D65*25%)-(MAX(0,(D65-300))*5%)-(MAX(0,(D65-600))*5%)-(MAX(0,(D65-1200))*5%)-(MAX(0,(D65-1500))*5%))*C65 -> -8719390.7 | G65: =-E65*$F$2 -> -10296741 | H65: =-E65*$C$3 -> -16474785 | I65: =+E65+F65+G65+H65 -> 5696046.4 | J65: =+J64+I65 -> 1.6227144e+08

Sheet Channel 3_calculations
B1: Monthl_premium | C1: =+'Inputs & Assuptions'!$D$2 -> 300 | E1: Commission_rate | F1: 0.2
B2: Premium_Increase | C2: =+'Inputs & Assuptions'!$D$3 -> 0.05 | E2: Expenses_rate | F2: =+'Inputs & Assuptions'!$D$7 -> 0.25
B3: Gross Claim Ratio | C3: =+'Inputs & Assuptions'!$D$8 -> 0.4
A5: Months | B5: New_sales | C5: Active Policies | D5: Premium | E5: Gross_Premium | F5: Commission | G5: Expenses | H5: Claims | I5: Net Gain/Loss | J5: CummulativeNet Gain/Loss
A6: 1 | B6: =+'Channel 3 Sales'!C6 -> 978 | C6: {=+TRANSPOSE('Channel 3 Sales'!$F$67:$BM$67)} -> 978 | D6: =IF(MOD($A6, 12) = 0, $C$1 * 1.05, $C$1) -> 300 | E6: =+C6*D6 -> 293400 | F6: =-C6*D6*$F$1 -> -58680 | G6: =-E6*$F$2 -> -73350 | H6: =-E6*$C$3 -> -117360 | I6: =+E6+F6+G6+H6 -> 44010 | J6: =+I6 -> 44010
A7: =+A6+1 -> 2 | B7: =+'Channel 3 Sales'!C7 -> 978 | C7: 1951.11 | D7: =IF(MOD($A7-1, 12) = 0, D6 * 1.05, D6) -> 300 | E7: =+C7*D7 -> 585333 | F7: =-C7*D7*$F$1 -> -117066.6 | G7: =-E7*$F$2 -> -146333.25 | H7: =-E7*$C$3 -> -234133.2 | I7: =+E7+F7+G7+H7 -> 87799.95 | J7: =+J6+I7 -> 131809.95
A8: =+A7+1 -> 3 | B8: =+'Channel 3 Sales'!C8 -> 978 | C8: 2920.5222 | D8: =IF(MOD($A8-1, 12) = 0, D7 * 1.05, D7) -> 300 | E8: =+C8*D8 -> 876156.65 | F8: =-C8*D8*$F$1 -> -175231.33 | G8: =-E8*$F$2 -> -219039.16 | H8: =-E8*$C$3 -> -350462.66 | I8: =+E8+F8+G8+H8 -> 131423.5 | J8: =+J7+I8 -> 263233.45
A9: =+A8+1 -> 4 | B9: =+'Channel 3 Sales'!C9 -> 978 | C9: 3887.5108 | D9: =IF(MOD($A9-1, 12) = 0, D8 * 1.05, D8) -> 300 | E9: =+C9*D9 -> 1166253.3 | F9: =-C9*D9*$F$1 -> -233250.65 | G9: =-E9*$F$2 -> -291563.31 | H9: =-E9*$C$3 -> -466501.3 | I9: =+E9+F9+G9+H9 -> 174937.99 | J9: =+J8+I9 -> 438171.44
A10: =+A9+1 -> 5 | B10: =+'Channel 3 Sales'!C10 -> 978 | C10: 4852.2754 | D10: =IF(MOD($A10-1, 12) = 0, D9 * 1.05, D9) -> 300 | E10: =+C10*D10 -> 1455682.6 | F10: =-C10*D10*$F$1 -> -291136.52 | G10: =-E10*$F$2 -> -363920.66 | H10: =-E10*$C$3 -> -582273.05 | I10: =+E10+F10+G10+H10 -> 218352.39 | J10: =+J9+I10 -> 656523.83
A11: =+A10+1 -> 6 | B11: =+'Channel 3 Sales'!C11 -> 978 | C11: 5815.1105 | D11: =IF(MOD($A11-1, 12) = 0, D10 * 1.05, D10) -> 300 | E11: =+C11*D11 -> 1744533.1 | F11: =-C11*D11*$F$1 -> -348906.63 | G11: =-E11*$F$2 -> -436133.28 | H11: =-E11*$C$3 -> -697813.26 | I11: =+E11+F11+G11+H11 -> 261679.97 | J11: =+J10+I11 -> 918203.8
A12: =+A11+1 -> 7 | B12: =+'Channel 3 Sales'!C12 -> 978 | C12: 6776.2124 | D12: =IF(MOD($A12-1, 12) = 0, D11 * 1.05, D11) -> 300 | E12: =+C12*D12 -> 2032863.7 | F12: =-C12*D12*$F$1 -> -406572.74 | G12: =-E12*$F$2 -> -508215.93 | H12: =-E12*$C$3 -> -813145.49 | I12: =+E12+F12+G12+H12 -> 304929.56 | J12: =+J11+I12 -> 1223133.4
A13: =+A12+1 -> 8 | B13: =+'Channel 3 Sales'!C13 -> 978 | C13: 7735.8727 | D13: =IF(MOD($A13-1, 12) = 0, D12 * 1.05, D12) -> 300 | E13: =+C13*D13 -> 2320761.8 | F13: =-C13*D13*$F$1 -> -464152.36 | G13: =-E13*$F$2 -> -580190.45 | H13: =-E13*$C$3 -> -928304.72 | I13: =+E13+F13+G13+H13 -> 348114.27 | J13: =+J12+I13 -> 1571247.6
A14: =+A13+1 -> 9 | B14: =+'Channel 3 Sales'!C14 -> 978 | C14: 8694.2854 | D14: =IF(MOD($A14-1, 12) = 0, D13 * 1.05, D13) -> 300 | E14: =+C14*D14 -> 2608285.6 | F14: =-C14*D14*$F$1 -> -521657.13 | G14: =-E14*$F$2 -> -652071.41 | H14: =-E14*$C$3 -> -1043314.3 | I14: =+E14+F14+G14+H14 -> 391242.84 | J14: =+J13+I14 -> 1962490.5
A15: =+A14+1 -> 10 | B15: =+'Channel 3 Sales'!C15 -> 978 | C15: 9651.7398 | D15: =IF(MOD($A15-1, 12) = 0, D14 * 1.05, D14) -> 300 | E15: =+C15*D15 -> 2895521.9 | F15: =-C15*D15*$F$1 -> -579104.39 | G15: =-E15*$F$2 -> -723880.48 | H15: =-E15*$C$3 -> -1158208.8 | I15: =+E15+F15+G15+H15 -> 434328.29 | J15: =+J14+I15 -> 2396818.8
A16: =+A15+1 -> 11 | B16: =+'Channel 3 Sales'!C16 -> 978 | C16: 10608.428 | D16: =IF(MOD($A16-1, 12) = 0, D15 * 1.05, D15) -> 300 | E16: =+C16*D16 -> 3182528.4 | F16: =-C16*D16*$F$1 -> -636505.69 | G16: =-E16*$F$2 -> -795632.11 | H16: =-E16*$C$3 -> -1273011.4 | I16: =+E16+F16+G16+H16 -> 477379.26 | J16: =+J15+I16 -> 2874198
A17: =+A16+1 -> 12 | B17: =+'Channel 3 Sales'!C17 -> 978 | C17: 11564.638 | D17: =IF(MOD($A17-1, 12) = 0, D16 * 1.05, D16) -> 300 | E17: =+C17*D17 -> 3469391.4 | F17: =-C17*D17*$F$1 -> -693878.29 | G17: =-E17*$F$2 -> -867347.86 | H17: =-E17*$C$3 -> -1387756.6 | I17: =+E17+F17+G17+H17 -> 520408.72 | J17: =+J16+I17 -> 3394606.7
A18: =+A17+1 -> 13 | B18: =+'Channel 3 Sales'!C18 -> 1026.9 | C18: 12569.27 | D18: =IF(MOD($A18-1, 12) = 0, D17 * 1.05, D17) -> 315 | E18: =+C18*D18 -> 3959320.1 | F18: =-C18*D18*$F$1 -> -791864.01 | G18: =-E18*$F$2 -> -989830.02 | H18: =-E18*$C$3 -> -1583728 | I18: =+E18+F18+G18+H18 -> 593898.01 | J18: =+J17+I18 -> 3988504.8
... A65: =+A64+1 -> 60 | B65: =+'Channel 3 Sales'!C65 -> 1188.7651 | C65: 62930.252 | D65: =IF(MOD($A65-1, 12) = 0, D64 * 1.05, D64) -> 364.65188 | E65: =+C65*D65 -> 22947634 | F65: =-C65*D65*$F$1 -> -4589526.9 | G65: =-E65*$F$2 -> -5736908.6 | H65: =-E65*$C$3 -> -9179053.8 | I65: =+E65+F65+G65+H65 -> 3442145.2 | J65: =+J64+I65 -> 95952943

Sheet Channel 1 Sales
F2: New Sales | G2: =+'Inputs & Assuptions'!$B$4 -> 6000
F3: Sales Increase | G3: =+'Inputs & Assuptions'!$B$5 -> 0.05
B5: NEW_Monthly_Sales_Inc_NTU | C5: NEW_Monthly_Sales_Exc_NTU | E5: Duration | F5: 1 | G5: =+F5+1 -> 2 | H5: =+G5+1 -> 3 | I5: =+H5+1 -> 4 | J5: =+I5+1 -> 5 | K5: =+J5+1 -> 6 | L5: =+K5+1 -> 7 | M5: =+L5+1 -> 8 | N5: =+M5+1 -> 9 | ... BM5: =+BL5+1 -> 60
A6: 1 | B6: =IF(MOD($A6, 12) = 0, $G$2 * 1.05, $G$2) -> 6000 | C6: =$B6*(1-'Inputs & Assuptions'!$B$12) -> 3480 | E6: 1 | F6: =+$C6 -> 3480 | G6: {=IF(COLUMN() - ($E6 + 5) < 0, 0, IF(COLUMN() - ($E6 + 5) = 0, $F6, F6 * (1 - IFERROR(INDEX('Inputs & Assuptions'!$B$13:$B$72, COLUMN() - ($E6 + 5)), 0)) ) )} -> 3114.6 | H6: {=IF(COLUMN() - ($E6 + 5) < 0, 0, IF(COLUMN() - ($E6 + 5) = 0, $F6, G6 * (1 - IFERROR(INDEX('Inputs & Assuptions'!$B$13:$B$72, COLUMN() - ($E6 + 5)), 0)) ) )} -> 2865.432 | I6: {=IF(COLUMN() - ($E6 + 5) < 0, 0, IF(COLUMN() - ($E6 + 5) = 0, $F6, H6 * (1 - IFERROR(INDEX('Inputs & Assuptions'!$B$13:$B$72, COLUMN() - ($E6 + 5)), 0)) ) )} -> 2707.8332 | J6: {=IF(COLUMN() - ($E6 + 5) < 0, 0, IF(COLUMN() - ($E6 + 5) = 0, $F6, I6 * (1 - IFERROR(INDEX('Inputs & Assuptions'!$B$13:$B$72, COLUMN() - ($E6 + 5)), 0)) ) )} -> 2572.4416 | K6: {=IF(COLUMN() - ($E6 + 5) < 0, 0, IF(COLUMN() - ($E6 + 5) = 0, $F6, J6 * (1 - IFERROR(INDEX('Inputs & Assuptions'!$B$13:$B$72, COLUMN() - ($E6 + 5)), 0)) ) )} -> 2456.6817 | L6: {=IF(COLUMN() - ($E6 + 5) < 0, 0, IF(COLUMN() - ($E6 + 5) = 0, $F6, K6 * (1 - IFERROR(INDEX('Inputs & Assuptions'!$B$13:$B$72, COLUMN() - ($E6 + 5)), 0)) ) )} -> 2358.4144 | M6: {=IF(COLUMN() - ($E6 + 5) < 0, 0, IF(COLUMN() - ($E6 + 5) = 0, $F6, L6 * (1 - IFERROR(INDEX('Inputs & Assuptions'!$B$13:$B$72, COLUMN() - ($E6 + 5)), 0)) ) )} -> 2275.8699 | N6: {=IF(COLUMN() - ($E6 + 5) < 0, 0, IF(COLUMN() - ($E6 + 5) = 0, $F6, M6 * (1 - IFERROR(INDEX('Inputs & Assuptions'!$B$13:$B$72, COLUMN() - ($E6 + 5)), 0)) ) )} -> 2207.5938 | ... BM6: {=IF(COLUMN() - ($E6 + 5) < 0, 0, IF(COLUMN() - ($E6 + 5) = 0, $F6, BL6 * (1 - IFERROR(INDEX('Inputs & Assuptions'!$B$13:$B$72, COLUMN() - ($E6 + 5)), 0)) ) )} -> 1289.0638
A7: =A6+1 -> 2 | B7: =IF(MOD($A7-1, 12) = 0, $B6 * 1.05, $B6) -> 6000 | C7: =$B7*(1-'Inputs & Assuptions'!$B$12) -> 3480 | E7: =E6+1 -> 2 | G7: =+$C7 -> 3480 | H7: {=IF(COLUMN() - ($E7 + 5) < 0, 0, IF(COLUMN() - ($E7 + 5) = 0, $F7, G7 * (1 - IFERROR(INDEX('Inputs & Assuptions'!$B$13:$B$72, COLUMN() - ($E7 + 5)), 0)) ) )} -> 3114.6 | I7: {=IF(COLUMN() - ($E7 + 5) < 0, 0, IF(COLUMN() - ($E7 + 5) = 0, $F7, H7 * (1 - IFERROR(INDEX('Inputs & Assuptions'!$B$13:$B$72, COLUMN() - ($E7 + 5)), 0)) ) )} -> 2865.432 | J7: {=IF(COLUMN() - ($E7 + 5) < 0, 0, IF(COLUMN() - ($E7 + 5) = 0, $F7, I7 * (1 - IFERROR(INDEX('Inputs & Assuptions'!$B$13:$B$72, COLUMN() - ($E7 + 5)), 0)) ) )} -> 2707.8332 | K7: {=IF(COLUMN() - ($E7 + 5) < 0, 0, IF(COLUMN() - ($E7 + 5) = 0, $F7, J7 * (1 - IFERROR(INDEX('Inputs & Assuptions'!$B$13:$B$72, COLUMN() - ($E7 + 5)), 0)) ) )} -> 2572.4416 | L7: {=IF(COLUMN() - ($E7 + 5) < 0, 0, IF(COLUMN() - ($E7 + 5) = 0, $F7, K7 * (1 - IFERROR(INDEX('Inputs & Assuptions'!$B$13:$B$72, COLUMN() - ($E7 + 5)), 0)) ) )} -> 2456.6817 | M7: {=IF(COLUMN() - ($E7 + 5) < 0, 0, IF(COLUMN() - ($E7 + 5) = 0, $F7, L7 * (1 - IFERROR(INDEX('Inputs & Assuptions'!$B$13:$B$72, COLUMN() - ($E7 + 5)), 0)) ) )} -> 2358.4144 | N7: {=IF(COLUMN() - ($E7 + 5) < 0, 0, IF(COLUMN() - ($E7 + 5) = 0, $F7, M7 * (1 - IFERROR(INDEX('Inputs & Assuptions'!$B$13:$B$72, COLUMN() - ($E7 + 5)), 0)) ) )} -> 2275.8699 | O7: {=IF(COLUMN() - ($E7 + 5) < 0, 0, IF(COLUMN() - ($E7 + 5) = 0, $F7, N7 * (1 - IFERROR(INDEX('Inputs & Assuptions'!$B$13:$B$72, COLUMN() - ($E7 + 5)), 0)) ) )} -> 2207.5938 | ... BM7: {=IF(COLUMN() - ($E7 + 5) < 0, 0, IF(COLUMN() - ($E7 + 5) = 0, $F7, BL7 * (1 - IFERROR(INDEX('Inputs & Assuptions'!$B$13:$B$72, COLUMN() - ($E7 + 5)), 0)) ) )} -> 1302.0846
A8: =A7+1 -> 3 | B8: =IF(MOD($A8-1, 12) = 0, $B7 * 1.05, $B7) -> 6000 | C8: =$B8*(1-'Inputs & Assuptions'!$B$12) -> 3480 | E8: =E7+1 -> 3 | H8: =+$C8 -> 3480 | I8: {=IF(COLUMN() - ($E8 + 5) < 0, 0, IF(COLUMN() - ($E8 + 5) = 0, $F8, H8 * (1 - IFERROR(INDEX('Inputs & Assuptions'!$B$13:$B$72, COLUMN() - ($E8 + 5)), 0)) ) )} -> 3114.6 | J8: {=IF(COLUMN() - ($E8 + 5) < 0, 0, IF(COLUMN() - ($E8 + 5) = 0, $F8, I8 * (1 - IFERROR(INDEX('Inputs & Assuptions'!$B$13:$B$72, COLUMN() - ($E8 + 5)), 0)) ) )} -> 2865.432 | K8: {=IF(COLUMN() - ($E8 + 5) < 0, 0, IF(COLUMN() - ($E8 + 5) = 0, $F8, J8 * (1 - IFERROR(INDEX('Inputs & Assuptions'!$B$13:$B$72, COLUMN() - ($E8 + 5)), 0)) ) )} -> 2707.8332 | L8: {=IF(COLUMN() - ($E8 + 5) < 0, 0, IF(COLUMN() - ($E8 + 5) = 0, $F8, K8 * (1 - IFERROR(INDEX('Inputs & Assuptions'!$B$13:$B$72, COLUMN() - ($E8 + 5)), 0)) ) )} -> 2572.4416 | M8: {=IF(COLUMN() - ($E8 + 5) < 0, 0, IF(COLUMN() - ($E8 + 5) = 0, $F8, L8 * (1 - IFERROR(INDEX('Inputs & Assuptions'!$B$13:$B$72, COLUMN() - ($E8 + 5)), 0)) ) )} -> 2456.6817 | N8: {=IF(COLUMN() - ($E8 + 5) < 0, 0, IF(COLUMN() - ($E8 + 5) = 0, $F8, M8 * (1 - IFERROR(INDEX('Inputs & Assuptions'!$B$13:$B$72, COLUMN() - ($E8 + 5)), 0)) ) )} -> 2358.4144 | O8: {=IF(COLUMN() - ($E8 + 5) < 0, 0, IF(COLUMN() - ($E8 + 5) = 0, $F8, N8 * (1 - IFERROR(INDEX('Inputs & Assuptions'!$B$13:$B$72, COLUMN() - ($E8 + 5)), 0)) ) )} -> 2275.8699 | P8: {=IF(COLUMN() - ($E8 + 5) < 0, 0, IF(COLUMN() - ($E8 + 5) = 0, $F8, O8 * (1 - IFERROR(INDEX('Inputs & Assuptions'!$B$13:$B$72, COLUMN() - ($E8 + 5)), 0)) ) )} -> 2207.5938 | ... BM8: {=IF(COLUMN() - ($E8 + 5) < 0, 0, IF(COLUMN() - ($E8 + 5) = 0, $F8, BL8 * (1 - IFERROR(INDEX('Inputs & Assuptions'!$B$13:$B$72, COLUMN() - ($E8 + 5)), 0)) ) )} -> 1315.237
A9: =A8+1 -> 4 | B9: =IF(MOD($A9-1, 12) = 0, $B8 * 1.05, $B8) -> 6000 | C9: =$B9*(1-'Inputs & Assuptions'!$B$12) -> 3480 | E9: =E8+1 -> 4 | I9: =+$C9 -> 3480 | J9: {=IF(COLUMN() - ($E9 + 5) < 0, 0, IF(COLUMN() - ($E9 + 5) = 0, $F9, I9 * (1 - IFERROR(INDEX('Inputs & Assuptions'!$B$13:$B$72, COLUMN() - ($E9 + 5)), 0)) ) )} -> 3114.6 | K9: {=IF(COLUMN() - ($E9 + 5) < 0, 0, IF(COLUMN() - ($E9 + 5) = 0, $F9, J9 * (1 - IFERROR(INDEX('Inputs & Assuptions'!$B$13:$B$72, COLUMN() - ($E9 + 5)), 0)) ) )} -> 2865.432 | L9: {=IF(COLUMN() - ($E9 + 5) < 0, 0, IF(COLUMN() - ($E9 + 5) = 0, $F9, K9 * (1 - IFERROR(INDEX('Inputs & Assuptions'!$B$13:$B$72, COLUMN() - ($E9 + 5)), 0)) ) )} -> 2707.8332 | M9: {=IF(COLUMN() - ($E9 + 5) < 0, 0, IF(COLUMN() - ($E9 + 5) = 0, $F9, L9 * (1 - IFERROR(INDEX('Inputs & Assuptions'!$B$13:$B$72, COLUMN() - ($E9 + 5)), 0)) ) )} -> 2572.4416 | N9: {=IF(COLUMN() - ($E9 + 5) < 0, 0, IF(COLUMN() - ($E9 + 5) = 0, $F9, M9 * (1 - IFERROR(INDEX('Inputs & Assuptions'!$B$13:$B$72, COLUMN() - ($E9 + 5)), 0)) ) )} -> 2456.6817 | O9: {=IF(COLUMN() - ($E9 + 5) < 0, 0, IF(COLUMN() - ($E9 + 5) = 0, $F9, N9 * (1 - IFERROR(INDEX('Inputs & Assuptions'!$B$13:$B$72, COLUMN() - ($E9 + 5)), 0)) ) )} -> 2358.4144 | P9: {=IF(COLUMN() - ($E9 + 5) < 0, 0, IF(COLUMN() - ($E9 + 5) = 0, $F9, O9 * (1 - IFERROR(INDEX('Inputs & Assuptions'!$B$13:$B$72, COLUMN() - ($E9 + 5)), 0)) ) )} -> 2275.8699 | Q9: {=IF(COLUMN() - ($E9 + 5) < 0, 0, IF(COLUMN() - ($E9 + 5) = 0, $F9, P9 * (1 - IFERROR(INDEX('Inputs & Assuptions'!$B$13:$B$72, COLUMN() - ($E9 + 5)), 0)) ) )} -> 2207.5938 | ... BM9: {=IF(COLUMN() - ($E9 + 5) < 0, 0, IF(COLUMN() - ($E9 + 5) = 0, $F9, BL9 * (1 - IFERROR(INDEX('Inputs & Assuptions'!$B$13:$B$72, COLUMN() - ($E9 + 5)), 0)) ) )} -> 1328.5222
A10: =A9+1 -> 5 | B10: =IF(MOD($A10-1, 12) = 0, $B9 * 1.05, $B9) -> 6000 | C10: =$B10*(1-'Inputs & Assuptions'!$B$12) -> 3480 | E10: =E9+1 -> 5 | J10: =+$C10 -> 3480 | K10: {=IF(COLUMN() - ($E10 + 5) < 0, 0, IF(COLUMN() - ($E10 + 5) = 0, $F10, J10 * (1 - IFERROR(INDEX('Inputs & Assuptions'!$B$13:$B$72, COLUMN() - ($E10 + 5)), 0)) ) )} -> 3114.6 | L10: {=IF(COLUMN() - ($E10 + 5) < 0, 0, IF(COLUMN() - ($E10 + 5) = 0, $F10, K10 * (1 - IFERROR(INDEX('Inputs & Assuptions'!$B$13:$B$72, COLUMN() - ($E10 + 5)), 0)) ) )} -> 2865.432 | M10: {=IF(COLUMN() - ($E10 + 5) < 0, 0, IF(COLUMN() - ($E10 + 5) = 0, $F10, L10 * (1 - IFERROR(INDEX('Inputs & Assuptions'!$B$13:$B$72, COLUMN() - ($E10 + 5)), 0)) ) )} -> 2707.8332 | N10: {=IF(COLUMN() - ($E10 + 5) < 0, 0, IF(COLUMN() - ($E10 + 5) = 0, $F10, M10 * (1 - IFERROR(INDEX('Inputs & Assuptions'!$B$13:$B$72, COLUMN() - ($E10 + 5)), 0)) ) )} -> 2572.4416 | O10: {=IF(COLUMN() - ($E10 + 5) < 0, 0, IF(COLUMN() - ($E10 + 5) = 0, $F10, N10 * (1 - IFERROR(INDEX('Inputs & Assuptions'!$B$13:$B$72, COLUMN() - ($E10 + 5)), 0)) ) )} -> 2456.6817 | P10: {=IF(COLUMN() - ($E10 + 5) < 0, 0, IF(COLUMN() - ($E10 + 5) = 0, $F10, O10 * (1 - IFERROR(INDEX('Inputs & Assuptions'!$B$13:$B$72, COLUMN() - ($E10 + 5)), 0)) ) )} -> 2358.4144 | Q10: {=IF(COLUMN() - ($E10 + 5) < 0, 0, IF(COLUMN() - ($E10 + 5) = 0, $F10, P10 * (1 - IFERROR(INDEX('Inputs & Assuptions'!$B$13:$B$72, COLUMN() - ($E10 + 5)), 0)) ) )} -> 2275.8699 | R10: {=IF(COLUMN() - ($E10 + 5) < 0, 0, IF(COLUMN() - ($E10 + 5) = 0, $F10, Q10 * (1 - IFERROR(INDEX('Inputs & Assuptions'!$B$13:$B$72, COLUMN() - ($E10 + 5)), 0)) ) )} -> 2207.5938 | ... BM10: {=IF(COLUMN() - ($E10 + 5) < 0, 0, IF(COLUMN() - ($E10 + 5) = 0, $F10, BL10 * (1 - IFERROR(INDEX('Inputs & Assuptions'!$B$13:$B$72, COLUMN() - ($E10 + 5)), 0)) ) )} -> 1341.9416
A11: =A10+1 -> 6 | B11: =IF(MOD($A11-1, 12) = 0, $B10 * 1.05, $B10) -> 6000 | C11: =$B11*(1-'Inputs & Assuptions'!$B$12) -> 3480 | E11: =E10+1 -> 6 | K11: =+$C11 -> 3480 | L11: {=IF(COLUMN() - ($E11 + 5) < 0, 0, IF(COLUMN() - ($E11 + 5) = 0, $F11, K11 * (1 - IFERROR(INDEX('Inputs & Assuptions'!$B$13:$B$72, COLUMN() - ($E11 + 5)), 0)) ) )} -> 3114.6 | M11: {=IF(COLUMN() - ($E11 + 5) < 0, 0, IF(COLUMN() - ($E11 + 5) = 0, $F11, L11 * (1 - IFERROR(INDEX('Inputs & Assuptions'!$B$13:$B$72, COLUMN() - ($E11 + 5)), 0)) ) )} -> 2865.432 | N11: {=IF(COLUMN() - ($E11 + 5) < 0, 0, IF(COLUMN() - ($E11 + 5) = 0, $F11, M11 * (1 - IFERROR(INDEX('Inputs & Assuptions'!$B$13:$B$72, COLUMN() - ($E11 + 5)), 0)) ) )} -> 2707.8332 | O11: {=IF(COLUMN() - ($E11 + 5) < 0, 0, IF(COLUMN() - ($E11 + 5) = 0, $F11, N11 * (1 - IFERROR(INDEX('Inputs & Assuptions'!$B$13:$B$72, COLUMN() - ($E11 + 5)), 0)) ) )} -> 2572.4416 | P11: {=IF(COLUMN() - ($E11 + 5) < 0, 0, IF(COLUMN() - ($E11 + 5) = 0, $F11, O11 * (1 - IFERROR(INDEX('Inputs & Assuptions'!$B$13:$B$72, COLUMN() - ($E11 + 5)), 0)) ) )} -> 2456.6817 | Q11: {=IF(COLUMN() - ($E11 + 5) < 0, 0, IF(COLUMN() - ($E11 + 5) = 0, $F11, P11 * (1 - IFERROR(INDEX('Inputs & Assuptions'!$B$13:$B$72, COLUMN() - ($E11 + 5)), 0)) ) )} -> 2358.4144 | R11: {=IF(COLUMN() - ($E11 + 5) < 0, 0, IF(COLUMN() - ($E11 + 5) = 0, $F11, Q11 * (1 - IFERROR(INDEX('Inputs & Assuptions'!$B$13:$B$72, COLUMN() - ($E11 + 5)), 0)) ) )} -> 2275.8699 | S11: {=IF(COLUMN() - ($E11 + 5) < 0, 0, IF(COLUMN() - ($E11 + 5) = 0, $F11, R11 * (1 - IFERROR(INDEX('Inputs & Assuptions'!$B$13:$B$72, COLUMN() - ($E11 + 5)), 0)) ) )} -> 2207.5938 | ... BM11: {=IF(COLUMN() - ($E11 + 5) < 0, 0, IF(COLUMN() - ($E11 + 5) = 0, $F11, BL11 * (1 - IFERROR(INDEX('Inputs & Assuptions'!$B$13:$B$72, COLUMN() - ($E11 + 5)), 0)) ) )} -> 1355.4966
A12: =A11+1 -> 7 | B12: =IF(MOD($A12-1, 12) = 0, $B11 * 1.05, $B11) -> 6000 | C12: =$B12*(1-'Inputs & Assuptions'!$B$12) -> 3480 | E12: =E11+1 -> 7 | L12: =+$C12 -> 3480 | M12: {=IF(COLUMN() - ($E12 + 5) < 0, 0, IF(COLUMN() - ($E12 + 5) = 0, $F12, L12 * (1 - IFERROR(INDEX('Inputs & Assuptions'!$B$13:$B$72, COLUMN() - ($E12 + 5)), 0)) ) )} -> 3114.6 | N12: {=IF(COLUMN() - ($E12 + 5) < 0, 0, IF(COLUMN() - ($E12 + 5) = 0, $F12, M12 * (1 - IFERROR(INDEX('Inputs & Assuptions'!$B$13:$B$72, COLUMN() - ($E12 + 5)), 0)) ) )} -> 2865.432 | O12: {=IF(COLUMN() - ($E12 + 5) < 0, 0, IF(COLUMN() - ($E12 + 5) = 0, $F12, N12 * (1 - IFERROR(INDEX('Inputs & Assuptions'!$B$13:$B$72, COLUMN() - ($E12 + 5)), 0)) ) )} -> 2707.8332 | P12: {=IF(COLUMN() - ($E12 + 5) < 0, 0, IF(COLUMN() - ($E12 + 5) = 0, $F12, O12 * (1 - IFERROR(INDEX('Inputs & Assuptions'!$B$13:$B$72, COLUMN() - ($E12 + 5)), 0)) ) )} -> 2572.4416 | Q12: {=IF(COLUMN() - ($E12 + 5) < 0, 0, IF(COLUMN() - ($E12 + 5) = 0, $F12, P12 * (1 - IFERROR(INDEX('Inputs & Assuptions'!$B$13:$B$72, COLUMN() - ($E12 + 5)), 0)) ) )} -> 2456.6817 | R12: {=IF(COLUMN() - ($E12 + 5) < 0, 0, IF(COLUMN() - ($E12 + 5) = 0, $F12, Q12 * (1 - IFERROR(INDEX('Inputs & Assuptions'!$B$13:$B$72, COLUMN() - ($E12 + 5)), 0)) ) )} -> 2358.4144 | S12: {=IF(COLUMN() - ($E12 + 5) < 0, 0, IF(COLUMN() - ($E12 + 5) = 0, $F12, R12 * (1 - IFERROR(INDEX('Inputs & Assuptions'!$B$13:$B$72, COLUMN() - ($E12 + 5)), 0)) ) )} -> 2275.8699 | T12: {=IF(COLUMN() - ($E12 + 5) < 0, 0, IF(COLUMN() - ($E12 + 5) = 0, $F12, S12 * (1 - IFERROR(INDEX('Inputs & Assuptions'!$B$13:$B$72, COLUMN() - ($E12 + 5)), 0)) ) )} -> 2207.5938 | ... BM12: {=IF(COLUMN() - ($E12 + 5) < 0, 0, IF(COLUMN() - ($E12 + 5) = 0, $F12, BL12 * (1 - IFERROR(INDEX('Inputs & Assuptions'!$B$13:$B$72, COLUMN() - ($E12 + 5)), 0)) ) )} -> 1369.1885
A13: =A12+1 -> 8 | B13: =IF(MOD($A13-1, 12) = 0, $B12 * 1.05, $B12) -> 6000 | C13: =$B13*(1-'Inputs & Assuptions'!$B$12) -> 3480 | E13: =E12+1 -> 8 | M13: =+$C13 -> 3480 | N13: {=IF(COLUMN() - ($E13 + 5) < 0, 0, IF(COLUMN() - ($E13 + 5) = 0, $F13, M13 * (1 - IFERROR(INDEX('Inputs & Assuptions'!$B$13:$B$72, COLUMN() - ($E13 + 5)), 0)) ) )} -> 3114.6 | O13: {=IF(COLUMN() - ($E13 + 5) < 0, 0, IF(COLUMN() - ($E13 + 5) = 0, $F13, N13 * (1 - IFERROR(INDEX('Inputs & Assuptions'!$B$13:$B$72, COLUMN() - ($E13 + 5)), 0)) ) )} -> 2865.432 | P13: {=IF(COLUMN() - ($E13 + 5) < 0, 0, IF(COLUMN() - ($E13 + 5) = 0, $F13, O13 * (1 - IFERROR(INDEX('Inputs & Assuptions'!$B$13:$B$72, COLUMN() - ($E13 + 5)), 0)) ) )} -> 2707.8332 | Q13: {=IF(COLUMN() - ($E13 + 5) < 0, 0, IF(COLUMN() - ($E13 + 5) = 0, $F13, P13 * (1 - IFERROR(INDEX('Inputs & Assuptions'!$B$13:$B$72, COLUMN() - ($E13 + 5)), 0)) ) )} -> 2572.4416 | R13: {=IF(COLUMN() - ($E13 + 5) < 0, 0, IF(COLUMN() - ($E13 + 5) = 0, $F13, Q13 * (1 - IFERROR(INDEX('Inputs & Assuptions'!$B$13:$B$72, COLUMN() - ($E13 + 5)), 0)) ) )} -> 2456.6817 | S13: {=IF(COLUMN() - ($E13 + 5) < 0, 0, IF(COLUMN() - ($E13 + 5) = 0, $F13, R13 * (1 - IFERROR(INDEX('Inputs & Assuptions'!$B$13:$B$72, COLUMN() - ($E13 + 5)), 0)) ) )} -> 2358.4144 | T13: {=IF(COLUMN() - ($E13 + 5) < 0, 0, IF(COLUMN() - ($E13 + 5) = 0, $F13, S13 * (1 - IFERROR(INDEX('Inputs & Assuptions'!$B$13:$B$72, COLUMN() - ($E13 + 5)), 0)) ) )} -> 2275.8699 | U13: {=IF(COLUMN() - ($E13 + 5) < 0, 0, IF(COLUMN() - ($E13 + 5) = 0, $F13, T13 * (1 - IFERROR(INDEX('Inputs & Assuptions'!$B$13:$B$72, COLUMN() - ($E13 + 5)), 0)) ) )} -> 2207.5938 | ... BM13: {=IF(COLUMN() - ($E13 + 5) < 0, 0, IF(COLUMN() - ($E13 + 5) = 0, $F13, BL13 * (1 - IFERROR(INDEX('Inputs & Assuptions'!$B$13:$B$72, COLUMN() - ($E13 + 5)), 0)) ) )} -> 1383.0187
A14: =A13+1 -> 9 | B14: =IF(MOD($A14-1, 12) = 0, $B13 * 1.05, $B13) -> 6000 | C14: =$B14*(1-'Inputs & Assuptions'!$B$12) -> 3480 | E14: =E13+1 -> 9 | N14: =+$C14 -> 3480 | O14: {=IF(COLUMN() - ($E14 + 5) < 0, 0, IF(COLUMN() - ($E14 + 5) = 0, $F14, N14 * (1 - IFERROR(INDEX('Inputs & Assuptions'!$B$13:$B$72, COLUMN() - ($E14 + 5)), 0)) ) )} -> 3114.6 | P14: {=IF(COLUMN() - ($E14 + 5) < 0, 0, IF(COLUMN() - ($E14 + 5) = 0, $F14, O14 * (1 - IFERROR(INDEX('Inputs & Assuptions'!$B$13:$B$72, COLUMN() - ($E14 + 5)), 0)) ) )} -> 2865.432 | Q14: {=IF(COLUMN() - ($E14 + 5) < 0, 0, IF(COLUMN() - ($E14 + 5) = 0, $F14, P14 * (1 - IFERROR(INDEX('Inputs & Assuptions'!$B$13:$B$72, COLUMN() - ($E14 + 5)), 0)) ) )} -> 2707.8332 | R14: {=IF(COLUMN() - ($E14 + 5) < 0, 0, IF(COLUMN() - ($E14 + 5) = 0, $F14, Q14 * (1 - IFERROR(INDEX('Inputs & Assuptions'!$B$13:$B$72, COLUMN() - ($E14 + 5)), 0)) ) )} -> 2572.4416 | S14: {=IF(COLUMN() - ($E14 + 5) < 0, 0, IF(COLUMN() - ($E14 + 5) = 0, $F14, R14 * (1 - IFERROR(INDEX('Inputs & Assuptions'!$B$13:$B$72, COLUMN() - ($E14 + 5)), 0)) ) )} -> 2456.6817 | T14: {=IF(COLUMN() - ($E14 + 5) < 0, 0, IF(COLUMN() - ($E14 + 5) = 0, $F14, S14 * (1 - IFERROR(INDEX('Inputs & Assuptions'!$B$13:$B$72, COLUMN() - ($E14 + 5)), 0)) ) )} -> 2358.4144 | U14: {=IF(COLUMN() - ($E14 + 5) < 0, 0, IF(COLUMN() - ($E14 + 5) = 0, $F14, T14 * (1 - IFERROR(INDEX('Inputs & Assuptions'!$B$13:$B$72, COLUMN() - ($E14 + 5)), 0)) ) )} -> 2275.8699 | V14: {=IF(COLUMN() - ($E14 + 5) < 0, 0, IF(COLUMN() - ($E14 + 5) = 0, $F14, U14 * (1 - IFERROR(INDEX('Inputs & Assuptions'!$B$13:$B$72, COLUMN() - ($E14 + 5)), 0)) ) )} -> 2207.5938 | ... BM14: {=IF(COLUMN() - ($E14 + 5) < 0, 0, IF(COLUMN() - ($E14 + 5) = 0, $F14, BL14 * (1 - IFERROR(INDEX('Inputs & Assuptions'!$B$13:$B$72, COLUMN() - ($E14 + 5)), 0)) ) )} -> 1396.9885
A15: =A14+1 -> 10 | B15: =IF(MOD($A15-1, 12) = 0, $B14 * 1.05, $B14) -> 6000 | C15: =$B15*(1-'Inputs & Assuptions'!$B$12) -> 3480 | E15: =E14+1 -> 10 | O15: =+$C15 -> 3480 | P15: {=IF(COLUMN() - ($E15 + 5) < 0, 0, IF(COLUMN() - ($E15 + 5) = 0, $F15, O15 * (1 - IFERROR(INDEX('Inputs & Assuptions'!$B$13:$B$72, COLUMN() - ($E15 + 5)), 0)) ) )} -> 3114.6 | Q15: {=IF(COLUMN() - ($E15 + 5) < 0, 0, IF(COLUMN() - ($E15 + 5) = 0, $F15, P15 * (1 - IFERROR(INDEX('Inputs & Assuptions'!$B$13:$B$72, COLUMN() - ($E15 + 5)), 0)) ) )} -> 2865.432 | R15: {=IF(COLUMN() - ($E15 + 5) < 0, 0, IF(COLUMN() - ($E15 + 5) = 0, $F15, Q15 * (1 - IFERROR(INDEX('Inputs & Assuptions'!$B$13:$B$72, COLUMN() - ($E15 + 5)), 0)) ) )} -> 2707.8332 | S15: {=IF(COLUMN() - ($E15 + 5) < 0, 0, IF(COLUMN() - ($E15 + 5) = 0, $F15, R15 * (1 - IFERROR(INDEX('Inputs & Assuptions'!$B$13:$B$72, COLUMN() - ($E15 + 5)), 0)) ) )} -> 2572.4416 | T15: {=IF(COLUMN() - ($E15 + 5) < 0, 0, IF(COLUMN() - ($E15 + 5) = 0, $F15, S15 * (1 - IFERROR(INDEX('Inputs & Assuptions'!$B$13:$B$72, COLUMN() - ($E15 + 5)), 0)) ) )} -> 2456.6817 | U15: {=IF(COLUMN() - ($E15 + 5) < 0, 0, IF(COLUMN() - ($E15 + 5) = 0, $F15, T15 * (1 - IFERROR(INDEX('Inputs & Assuptions'!$B$13:$B$72, COLUMN() - ($E15 + 5)), 0)) ) )} -> 2358.4144 | V15: {=IF(COLUMN() - ($E15 + 5) < 0, 0, IF(COLUMN() - ($E15 + 5) = 0, $F15, U15 * (1 - IFERROR(INDEX('Inputs & Assuptions'!$B$13:$B$72, COLUMN() - ($E15 + 5)), 0)) ) )} -> 2275.8699 | W15: {=IF(COLUMN() - ($E15 + 5) < 0, 0, IF(COLUMN() - ($E15 + 5) = 0, $F15, V15 * (1 - IFERROR(INDEX('Inputs & Assuptions'!$B$13:$B$72, COLUMN() - ($E15 + 5)), 0)) ) )} -> 2207.5938 | ... BM15: {=IF(COLUMN() - ($E15 + 5) < 0, 0, IF(COLUMN() - ($E15 + 5) = 0, $F15, BL15 * (1 - IFERROR(INDEX('Inputs & Assuptions'!$B$13:$B$72, COLUMN() - ($E15 + 5)), 0)) ) )} -> 1411.0995
A16: =A15+1 -> 11 | B16: =IF(MOD($A16-1, 12) = 0, $B15 * 1.05, $B15) -> 6000 | C16: =$B16*(1-'Inputs & Assuptions'!$B$12) -> 3480 | E16: =E15+1 -> 11 | P16: =+$C16 -> 3480 | Q16: {=IF(COLUMN() - ($E16 + 5) < 0, 0, IF(COLUMN() - ($E16 + 5) = 0, $F16, P16 * (1 - IFERROR(INDEX('Inputs & Assuptions'!$B$13:$B$72, COLUMN() - ($E16 + 5)), 0)) ) )} -> 3114.6 | R16: {=IF(COLUMN() - ($E16 + 5) < 0, 0, IF(COLUMN() - ($E16 + 5) = 0, $F16, Q16 * (1 - IFERROR(INDEX('Inputs & Assuptions'!$B$13:$B$72, COLUMN() - ($E16 + 5)), 0)) ) )} -> 2865.432 | S16: {=IF(COLUMN() - ($E16 + 5) < 0, 0, IF(COLUMN() - ($E16 + 5) = 0, $F16, R16 * (1 - IFERROR(INDEX('Inputs & Assuptions'!$B$13:$B$72, COLUMN() - ($E16 + 5)), 0)) ) )} -> 2707.8332 | T16: {=IF(COLUMN() - ($E16 + 5) < 0, 0, IF(COLUMN() - ($E16 + 5) = 0, $F16, S16 * (1 - IFERROR(INDEX('Inputs & Assuptions'!$B$13:$B$72, COLUMN() - ($E16 + 5)), 0)) ) )} -> 2572.4416 | U16: {=IF(COLUMN() - ($E16 + 5) < 0, 0, IF(COLUMN() - ($E16 + 5) = 0, $F16, T16 * (1 - IFERROR(INDEX('Inputs & Assuptions'!$B$13:$B$72, COLUMN() - ($E16 + 5)), 0)) ) )} -> 2456.6817 | V16: {=IF(COLUMN() - ($E16 + 5) < 0, 0, IF(COLUMN() - ($E16 + 5) = 0, $F16, U16 * (1 - IFERROR(INDEX('Inputs & Assuptions'!$B$13:$B$72, COLUMN() - ($E16 + 5)), 0)) ) )} -> 2358.4144 | W16: {=IF(COLUMN() - ($E16 + 5) < 0, 0, IF(COLUMN() - ($E16 + 5) = 0, $F16, V16 * (1 - IFERROR(INDEX('Inputs & Assuptions'!$B$13:$B$72, COLUMN() - ($E16 + 5)), 0)) ) )} -> 2275.8699 | X16: {=IF(COLUMN() - ($E16 + 5) < 0, 0, IF(COLUMN() - ($E16 + 5) = 0, $F16, W16 * (1 - IFERROR(INDEX('Inputs & Assuptions'!$B$13:$B$72, COLUMN() - ($E16 + 5)), 0)) ) )} -> 2207.5938 | ... BM16: {=IF(COLUMN() - ($E16 + 5) < 0, 0, IF(COLUMN() - ($E16 + 5) = 0, $F16, BL16 * (1 - IFERROR(INDEX('Inputs & Assuptions'!$B$13:$B$72, COLUMN() - ($E16 + 5)), 0)) ) )} -> 1425.3531
A17: =A16+1 -> 12 | B17: =IF(MOD($A17-1, 12) = 0, $B16 * 1.05, $B16) -> 6000 | C17: =$B17*(1-'Inputs & Assuptions'!$B$12) -> 3480 | E17: =E16+1 -> 12 | Q17: =+$C17 -> 3480 | R17: {=IF(COLUMN() - ($E17 + 5) < 0, 0, IF(COLUMN() - ($E17 + 5) = 0, $F17, Q17 * (1 - IFERROR(INDEX('Inputs & Assuptions'!$B$13:$B$72, COLUMN() - ($E17 + 5)), 0)) ) )} -> 3114.6 | S17: {=IF(COLUMN() - ($E17 + 5) < 0, 0, IF(COLUMN() - ($E17 + 5) = 0, $F17, R17 * (1 - IFERROR(INDEX('Inputs & Assuptions'!$B$13:$B$72, COLUMN() - ($E17 + 5)), 0)) ) )} -> 2865.432 | T17: {=IF(COLUMN() - ($E17 + 5) < 0, 0, IF(COLUMN() - ($E17 + 5) = 0, $F17, S17 * (1 - IFERROR(INDEX('Inputs & Assuptions'!$B$13:$B$72, COLUMN() - ($E17 + 5)), 0)) ) )} -> 2707.8332 | U17: {=IF(COLUMN() - ($E17 + 5) < 0, 0, IF(COLUMN() - ($E17 + 5) = 0, $F17, T17 * (1 - IFERROR(INDEX('Inputs & Assuptions'!$B$13:$B$72, COLUMN() - ($E17 + 5)), 0)) ) )} -> 2572.4416 | V17: {=IF(COLUMN() - ($E17 + 5) < 0, 0, IF(COLUMN() - ($E17 + 5) = 0, $F17, U17 * (1 - IFERROR(INDEX('Inputs & Assuptions'!$B$13:$B$72, COLUMN() - ($E17 + 5)), 0)) ) )} -> 2456.6817 | W17: {=IF(COLUMN() - ($E17 + 5) < 0, 0, IF(COLUMN() - ($E17 + 5) = 0, $F17, V17 * (1 - IFERROR(INDEX('Inputs & Assuptions'!$B$13:$B$72, COLUMN() - ($E17 + 5)), 0)) ) )} -> 2358.4144 | X17: {=IF(COLUMN() - ($E17 + 5) < 0, 0, IF(COLUMN() - ($E17 + 5) = 0, $F17, W17 * (1 - IFERROR(INDEX('Inputs & Assuptions'!$B$13:$B$72, COLUMN() - ($E17 + 5)), 0)) ) )} -> 2275.8699 | Y17: {=IF(COLUMN() - ($E17 + 5) < 0, 0, IF(COLUMN() - ($E17 + 5) = 0, $F17, X17 * (1 - IFERROR(INDEX('Inputs & Assuptions'!$B$13:$B$72, COLUMN() - ($E17 + 5)), 0)) ) )} -> 2207.5938 | ... BM17: {=IF(COLUMN() - ($E17 + 5) < 0, 0, IF(COLUMN() - ($E17 + 5) = 0, $F17, BL17 * (1 - IFERROR(INDEX('Inputs & Assuptions'!$B$13:$B$72, COLUMN() - ($E17 + 5)), 0)) ) )} -> 1439.7506
A18: =A17+1 -> 13 | B18: =IF(MOD($A18-1, 12) = 0, $B17 * 1.05, $B17) -> 6300 | C18: =$B18*(1-'Inputs & Assuptions'!$B$12) -> 3654 | E18: =E17+1 -> 13 | R18: =+$C18 -> 3654 | S18: {=IF(COLUMN() - ($E18 + 5) < 0, 0, IF(COLUMN() - ($E18 + 5) = 0, $F18, R18 * (1 - IFERROR(INDEX('Inputs & Assuptions'!$B$13:$B$72, COLUMN() - ($E18 + 5)), 0)) ) )} -> 3270.33 | T18: {=IF(COLUMN() - ($E18 + 5) < 0, 0, IF(COLUMN() - ($E18 + 5) = 0, $F18, S18 * (1 - IFERROR(INDEX('Inputs & Assuptions'!$B$13:$B$72, COLUMN() - ($E18 + 5)), 0)) ) )} -> 3008.7036 | U18: {=IF(COLUMN() - ($E18 + 5) < 0, 0, IF(COLUMN() - ($E18 + 5) = 0, $F18, T18 * (1 - IFERROR(INDEX('Inputs & Assuptions'!$B$13:$B$72, COLUMN() - ($E18 + 5)), 0)) ) )} -> 2843.2249 | V18: {=IF(COLUMN() - ($E18 + 5) < 0, 0, IF(COLUMN() - ($E18 + 5) = 0, $F18, U18 * (1 - IFERROR(INDEX('Inputs & Assuptions'!$B$13:$B$72, COLUMN() - ($E18 + 5)), 0)) ) )} -> 2701.0637 | W18: {=IF(COLUMN() - ($E18 + 5) < 0, 0, IF(COLUMN() - ($E18 + 5) = 0, $F18, V18 * (1 - IFERROR(INDEX('Inputs & Assuptions'!$B$13:$B$72, COLUMN() - ($E18 + 5)), 0)) ) )} -> 2579.5158 | X18: {=IF(COLUMN() - ($E18 + 5) < 0, 0, IF(COLUMN() - ($E18 + 5) = 0, $F18, W18 * (1 - IFERROR(INDEX('Inputs & Assuptions'!$B$13:$B$72, COLUMN() - ($E18 + 5)), 0)) ) )} -> 2476.3352 | Y18: {=IF(COLUMN() - ($E18 + 5) < 0, 0, IF(COLUMN() - ($E18 + 5) = 0, $F18, X18 * (1 - IFERROR(INDEX('Inputs & Assuptions'!$B$13:$B$72, COLUMN() - ($E18 + 5)), 0)) ) )} -> 2389.6634 | Z18: {=IF(COLUMN() - ($E18 + 5) < 0, 0, IF(COLUMN() - ($E18 + 5) = 0, $F18, Y18 * (1 - IFERROR(INDEX('Inputs & Assuptions'!$B$13:$B$72, COLUMN() - ($E18 + 5)), 0)) ) )} -> 2317.9735 | ... BM18: {=IF(COLUMN() - ($E18 + 5) < 0, 0, IF(COLUMN() - ($E18 + 5) = 0, $F18, BL18 * (1 - IFERROR(INDEX('Inputs & Assuptions'!$B$13:$B$72, COLUMN() - ($E18 + 5)), 0)) ) )} -> 1527.0082
A19: =A18+1 -> 14 | B19: =IF(MOD($A19-1, 12) = 0, $B18 * 1.05, $B18) -> 6300 | C19: =$B19*(1-'Inputs & Assuptions'!$B$12) -> 3654 | E19: =E18+1 -> 14 | S19: =+$C19 -> 3654 | T19: {=IF(COLUMN() - ($E19 + 5) < 0, 0, IF(COLUMN() - ($E19 + 5) = 0, $F19, S19 * (1 - IFERROR(INDEX('Inputs & Assuptions'!$B$13:$B$72, COLUMN() - ($E19 + 5)), 0)) ) )} -> 3270.33 | U19: {=IF(COLUMN() - ($E19 + 5) < 0, 0, IF(COLUMN() - ($E19 + 5) = 0, $F19, T19 * (1 - IFERROR(INDEX('Inputs & Assuptions'!$B$13:$B$72, COLUMN() - ($E19 + 5)), 0)) ) )} -> 3008.7036 | V19: {=IF(COLUMN() - ($E19 + 5) < 0, 0, IF(COLUMN() - ($E19 + 5) = 0, $F19, U19 * (1 - IFERROR(INDEX('Inputs & Assuptions'!$B$13:$B$72, COLUMN() - ($E19 + 5)), 0)) ) )} -> 2843.2249 | W19: {=IF(COLUMN() - ($E19 + 5) < 0, 0, IF(COLUMN() - ($E19 + 5) = 0, $F19, V19 * (1 - IFERROR(INDEX('Inputs & Assuptions'!$B$13:$B$72, COLUMN() - ($E19 + 5)), 0)) ) )} -> 2701.0637 | X19: {=IF(COLUMN() - ($E19 + 5) < 0, 0, IF(COLUMN() - ($E19 + 5) = 0, $F19, W19 * (1 - IFERROR(INDEX('Inputs & Assuptions'!$B$13:$B$72, COLUMN() - ($E19 + 5)), 0)) ) )} -> 2579.5158 | Y19: {=IF(COLUMN() - ($E19 + 5) < 0, 0, IF(COLUMN() - ($E19 + 5) = 0, $F19, X19 * (1 - IFERROR(INDEX('Inputs & Assuptions'!$B$13:$B$72, COLUMN() - ($E19 + 5)), 0)) ) )} -> 2476.3352 | Z19: {=IF(COLUMN() - ($E19 + 5) < 0, 0, IF(COLUMN() - ($E19 + 5) = 0, $F19, Y19 * (1 - IFERROR(INDEX('Inputs & Assuptions'!$B$13:$B$72, COLUMN() - ($E19 + 5)), 0)) ) )} -> 2389.6634 | AA19: {=IF(COLUMN() - ($E19 + 5) < 0, 0, IF(COLUMN() - ($E19 + 5) = 0, $F19, Z19 * (1 - IFERROR(INDEX('Inputs & Assuptions'!$B$13:$B$72, COLUMN() - ($E19 + 5)), 0)) ) )} -> 2317.9735 | ... BM19: {=IF(COLUMN() - ($E19 + 5) < 0, 0, IF(COLUMN() - ($E19 + 5) = 0, $F19, BL19 * (1 - IFERROR(INDEX('Inputs & Assuptions'!$B$13:$B$72, COLUMN() - ($E19 + 5)), 0)) ) )} -> 1542.4325
